Workbook

Sheet 1 - Staff Calendar View
A1: AI Fitness Trainers Master Schedule
I4: Week Controls
I5: Edit a Monday date to shift that week block.
B6: Location / Type | C6: =$J$7+0 -> 46209 | D6: =$J$7+1 -> 46210 | E6: =$J$7+2 -> 46211 | F6: =$J$7+3 -> 46212 | G6: =$J$7+4 -> 46213
A7: Wk 11 | B7: Clayton Drop-in | D7: Sener | E7: Sener | F7: Omila | I7: Wk 11 start (Mon) | J7: 46209
D8: Omila | E8: Ekachit | F8: Ekachit
E9: Advay
B10: Caulfield Drop-in | D10: Hailey | E10: Jamein | F10: Sener
D11: Ekachit | F11: Advay
D12: Advay | I12: Wk 12 start (Mon) | J12: 46216
B13: Webinar Faciliator | E13: Omila
B14: Webinar Support | E14: Grace
B15: DSRE All Hands Event | E15: Sener
E16: Ekachit | I16: Wk 13 start (Mon) | J16: 46223
E17: Advay
B18: Gemini Training | G18: All Staff
I20: Wk 14 start (Mon) | J20: 46230
B21: Location / Type | C21: =$J$12+0 -> 46216 | D21: =$J$12+1 -> 46217 | E21: =$J$12+2 -> 46218 | F21: =$J$12+3 -> 46219 | G21: =$J$12+4 -> 46220
A22: Wk 12 | B22: Clayton Drop-in | D22: Sener | E22: Grace | F22: Grace
D23: Jaemin | E23: Ekachit | F23: Ekachit
F24: Hailey | I24: Wk 15 start (Mon) | J24: 46237
B25: Caulfield Drop-in | D25: Hailey | E25: Omila | F25: Omila
E26: Sener | F26: Sener
E27: Jaemin | F27: Cass
B28: Climate Change Remote Drop-In | D28: Omila
D29: Grace
D30: Ekachit
B31: Webinar Support | E31: Cass
B32: Webinars Support Advanced AI: How Do AI Models Work? | I32: Wk 16 start (Mon) | J32: 46244
B34: In Person Sessions
I35: Wk 17 start (Mon) | J35: 46251
B38: Location / Type | C38: =$J$16+0 -> 46223 | D38: =$J$16+1 -> 46224 | E38: =$J$16+2 -> 46225 | F38: =$J$16+3 -> 46226 | G38: =$J$16+4 -> 46227 | I38: Wk 18 start (Mon) | J38: 46258
A39: Wk 13 | B39: Clayton Drop-in | D39: Advay | E39: Yunsoo | F39: Hailey
D40: Cass | E40: Ekachit | F40: Iris
E41: Cass | F41: Omila
B42: Caulfield Drop-in | D42: Sener | E42: Sener | F42: Sener
D43: Ekachit | E43: Advay | F43: Ekachit | I43: Wk 19 start (Mon) | J43: 46265
D44: Jaemin | E44: Grace | F44: Advay
E45: Josh (shadowing)
B46: Webinar Faciliator | E46: Grace
...

Sheet Webinar  Training Attendance 
A1: Date | B1: Time (AEST) | C1: Duration | D1: Session Title | E1: DeepNeuron Trainers
A2: 46155 | B2: 0.5 | C2: 1 hr | D2: Become AI Native | E2: Advay Kumar, Sener Sethi, Cass Whitehead, Grace Moss
A3: 46162 | B3: 0.5 | C3: 1 hr | D3: NotebookLM: Unlock Your Knowledge With AI | E3: Sener Sethi, Yunsoo Jin, Daksh Malhotra
A4: 46167 | B4: 0.375 | C4: 7 hrs | D4: Gemini Certification for Trainers | E4: Matthew Chung, Daksh Malhotra, Advay Kumar, Omila herath (attending training) Hailey Moffatt (attending training)
A5: 46169 | B5: 0.5 | C5: 1 hr | D5: Advanced AI: Agents | E5: Matthew Chung, Cass Whitehead
A6: 46176 | B6: 0.5 | C6: 1 hr | D6: AI at Monash: a practical introduction | E6: Hailey Moffatt, Iris Nguyen
A7: 46182 | B7: 0.5 | C7: 1 hr | D7: Creating Presentation Materials with Gemini | E7: Ekachit Hurreeram, Cass Whitehead
A8: 46188 | B8: 0.5 | C8: 1 hr | D8: Deep Dive into Gemini Deep Research | E8: Cass Whitehead, Daksh Malhotra
A9: 46196 | B9: 0.5 | C9: 1 hr | D9: Image creation with Gemini | E9: Ekachit Hurreeram,
A10: Tues, 30 June | B10: 0.375 | C10: 1 hr | D10: Gemini Certification for Trainers | E10: Ekachit Hurreeram, Omila Herath
A11: 46204 | B11: 0.5 | C11: 1 hr | D11: Advanced AI: Context Engineering | E11: Cass Whitehead, Advay Kumar
A12: 46211 | B12: 0.5 | C12: 1 hr | D12: ON HOLD: Introduction to Gemini Part 1 (Gems, Guided Learning & Canvas)
A13: 46218 | B13: 0.5 | C13: 1 hr | D13: Advanced AI: How Models Work

Sheet 3 - Shift Data (auto)
A1: Week | B1: Date | C1: Day | D1: Location / Type | E1: Time | F1: Staff | G1: Working With | H1: MatchRank
A2: ='1 - Staff Calendar View'!$A$7 -> Wk 11 | B2: ='1 - Staff Calendar View'!C$6 -> 46209 | C2: =TEXT(B2,"ddd") -> Mon | D2: ='1 - Staff Calendar View'!$B$7 -> Clayton Drop-in | E2: =VLOOKUP(D2,'1 - Staff Calendar View'!$I$49:$J$51,2,FALSE()) -> #N/A | F2: ='1 - Staff Calendar View'!C$7 | G2: =IF('1 - Staff Calendar View'!C$9="-","-",'1 - Staff Calendar View'!C$9) | H2: =IF('2 - My Shifts'!$C$4="","",IF(OR(F2="-",F2=""),"",IF(UPPER(TRIM(F2))=UPPER(TRIM('2 - My Shifts'!$C$4)),ROW()-1,""))) -> #REF!
A3: ='1 - Staff Calendar View'!$A$7 -> Wk 11 | B3: ='1 - Staff Calendar View'!C$6 -> 46209 | C3: =TEXT(B3,"ddd") -> Mon | D3: ='1 - Staff Calendar View'!$B$7 -> Clayton Drop-in | E3: =VLOOKUP(D3,'1 - Staff Calendar View'!$I$49:$J$51,2,FALSE()) -> #N/A | F3: ='1 - Staff Calendar View'!C$9 | G3: =IF('1 - Staff Calendar View'!C$7="-","-",'1 - Staff Calendar View'!C$7) | H3: =IF('2 - My Shifts'!$C$4="","",IF(OR(F3="-",F3=""),"",IF(UPPER(TRIM(F3))=UPPER(TRIM('2 - My Shifts'!$C$4)),ROW()-1,""))) -> #REF!
A4: ='1 - Staff Calendar View'!$A$7 -> Wk 11 | B4: ='1 - Staff Calendar View'!C$6 -> 46209 | C4: =TEXT(B4,"ddd") -> Mon | D4: ='1 - Staff Calendar View'!$B$10 -> Caulfield Drop-in | E4: =VLOOKUP(D4,'1 - Staff Calendar View'!$I$49:$J$51,2,FALSE()) -> 10:40AM-2:20PM | F4: ='1 - Staff Calendar View'!C$10 | G4: =IF('1 - Staff Calendar View'!C$12="-","-",'1 - Staff Calendar View'!C$12) | H4: =IF('2 - My Shifts'!$C$4="","",IF(OR(F4="-",F4=""),"",IF(UPPER(TRIM(F4))=UPPER(TRIM('2 - My Shifts'!$C$4)),ROW()-1,""))) -> #REF!
A5: ='1 - Staff Calendar View'!$A$7 -> Wk 11 | B5: ='1 - Staff Calendar View'!C$6 -> 46209 | C5: =TEXT(B5,"ddd") -> Mon | D5: ='1 - Staff Calendar View'!$B$10 -> Caulfield Drop-in | E5: =VLOOKUP(D5,'1 - Staff Calendar View'!$I$49:$J$51,2,FALSE()) -> 10:40AM-2:20PM | F5: ='1 - Staff Calendar View'!C$12 | G5: =IF('1 - Staff Calendar View'!C$10="-","-",'1 - Staff Calendar View'!C$10) | H5: =IF('2 - My Shifts'!$C$4="","",IF(OR(F5="-",F5=""),"",IF(UPPER(TRIM(F5))=UPPER(TRIM('2 - My Shifts'!$C$4)),ROW()-1,""))) -> #REF!
A6: ='1 - Staff Calendar View'!$A$7 -> Wk 11 | B6: ='1 - Staff Calendar View'!C$6 -> 46209 | C6: =TEXT(B6,"ddd") -> Mon | D6: ='1 - Staff Calendar View'!$B$13 -> Webinar Faciliator | E6: =VLOOKUP(D6,'1 - Staff Calendar View'!$I$49:$J$51,2,FALSE()) -> #N/A | F6: ='1 - Staff Calendar View'!C$13 | G6: =IF('1 - Staff Calendar View'!C$14="-","-",'1 - Staff Calendar View'!C$14) | H6: =IF('2 - My Shifts'!$C$4="","",IF(OR(F6="-",F6=""),"",IF(UPPER(TRIM(F6))=UPPER(TRIM('2 - My Shifts'!$C$4)),ROW()-1,""))) -> #REF!
A7: ='1 - Staff Calendar View'!$A$7 -> Wk 11 | B7: ='1 - Staff Calendar View'!C$6 -> 46209 | C7: =TEXT(B7,"ddd") -> Mon | D7: ='1 - Staff Calendar View'!$B$13 -> Webinar Faciliator | E7: =VLOOKUP(D7,'1 - Staff Calendar View'!$I$49:$J$51,2,FALSE()) -> #N/A | F7: ='1 - Staff Calendar View'!C$14 | G7: =IF('1 - Staff Calendar View'!C$13="-","-",'1 - Staff Calendar View'!C$13) | H7: =IF('2 - My Shifts'!$C$4="","",IF(OR(F7="-",F7=""),"",IF(UPPER(TRIM(F7))=UPPER(TRIM('2 - My Shifts'!$C$4)),ROW()-1,""))) -> #REF!
A8: ='1 - Staff Calendar View'!$A$7 -> Wk 11 | B8: ='1 - Staff Calendar View'!C$6 -> 46209 | C8: =TEXT(B8,"ddd") -> Mon | D8: ='1 - Staff Calendar View'!$B$16 | E8: =VLOOKUP(D8,'1 - Staff Calendar View'!$I$49:$J$51,2,FALSE()) -> #N/A | F8: ='1 - Staff Calendar View'!C$16 | G8: =IF('1 - Staff Calendar View'!C$18="-","-",'1 - Staff Calendar View'!C$18) | H8: =IF('2 - My Shifts'!$C$4="","",IF(OR(F8="-",F8=""),"",IF(UPPER(TRIM(F8))=UPPER(TRIM('2 - My Shifts'!$C$4)),ROW()-1,""))) -> #REF!
A9: ='1 - Staff Calendar View'!$A$7 -> Wk 11 | B9: ='1 - Staff Calendar View'!C$6 -> 46209 | C9: =TEXT(B9,"ddd") -> Mon | D9: ='1 - Staff Calendar View'!$B$16 | E9: =VLOOKUP(D9,'1 - Staff Calendar View'!$I$49:$J$51,2,FALSE()) -> #N/A | F9: ='1 - Staff Calendar View'!C$18 | G9: =IF('1 - Staff Calendar View'!C$16="-","-",'1 - Staff Calendar View'!C$16) | H9: =IF('2 - My Shifts'!$C$4="","",IF(OR(F9="-",F9=""),"",IF(UPPER(TRIM(F9))=UPPER(TRIM('2 - My Shifts'!$C$4)),ROW()-1,""))) -> #REF!
A10: ='1 - Staff Calendar View'!$A$7 -> Wk 11 | B10: ='1 - Staff Calendar View'!D$6 -> 46210 | C10: =TEXT(B10,"ddd") -> Tue | D10: ='1 - Staff Calendar View'!$B$7 -> Clayton Drop-in | E10: =VLOOKUP(D10,'1 - Staff Calendar View'!$I$49:$J$51,2,FALSE()) -> #N/A | F10: ='1 - Staff Calendar View'!D$7 -> Sener | G10: =IF('1 - Staff Calendar View'!D$9="-","-",'1 - Staff Calendar View'!D$9) | H10: =IF('2 - My Shifts'!$C$4="","",IF(OR(F10="-",F10=""),"",IF(UPPER(TRIM(F10))=UPPER(TRIM('2 - My Shifts'!$C$4)),ROW()-1,""))) -> #REF!
A11: ='1 - Staff Calendar View'!$A$7 -> Wk 11 | B11: ='1 - Staff Calendar View'!D$6 -> 46210 | C11: =TEXT(B11,"ddd") -> Tue | D11: ='1 - Staff Calendar View'!$B$7 -> Clayton Drop-in | E11: =VLOOKUP(D11,'1 - Staff Calendar View'!$I$49:$J$51,2,FALSE()) -> #N/A | F11: ='1 - Staff Calendar View'!D$9 | G11: =IF('1 - Staff Calendar View'!D$7="-","-",'1 - Staff Calendar View'!D$7) -> Sener | H11: =IF('2 - My Shifts'!$C$4="","",IF(OR(F11="-",F11=""),"",IF(UPPER(TRIM(F11))=UPPER(TRIM('2 - My Shifts'!$C$4)),ROW()-1,""))) -> #REF!
A12: ='1 - Staff Calendar View'!$A$7 -> Wk 11 | B12: ='1 - Staff Calendar View'!D$6 -> 46210 | C12: =TEXT(B12,"ddd") -> Tue | D12: ='1 - Staff Calendar View'!$B$10 -> Caulfield Drop-in | E12: =VLOOKUP(D12,'1 - Staff Calendar View'!$I$49:$J$51,2,FALSE()) -> 10:40AM-2:20PM | F12: ='1 - Staff Calendar View'!D$10 -> Hailey | G12: =IF('1 - Staff Calendar View'!D$12="-","-",'1 - Staff Calendar View'!D$12) -> Advay | H12: =IF('2 - My Shifts'!$C$4="","",IF(OR(F12="-",F12=""),"",IF(UPPER(TRIM(F12))=UPPER(TRIM('2 - My Shifts'!$C$4)),ROW()-1,""))) -> #REF!
A13: ='1 - Staff Calendar View'!$A$7 -> Wk 11 | B13: ='1 - Staff Calendar View'!D$6 -> 46210 | C13: =TEXT(B13,"ddd") -> Tue | D13: ='1 - Staff Calendar View'!$B$10 -> Caulfield Drop-in | E13: =VLOOKUP(D13,'1 - Staff Calendar View'!$I$49:$J$51,2,FALSE()) -> 10:40AM-2:20PM | F13: ='1 - Staff Calendar View'!D$12 -> Advay | G13: =IF('1 - Staff Calendar View'!D$10="-","-",'1 - Staff Calendar View'!D$10) -> Hailey | H13: =IF('2 - My Shifts'!$C$4="","",IF(OR(F13="-",F13=""),"",IF(UPPER(TRIM(F13))=UPPER(TRIM('2 - My Shifts'!$C$4)),ROW()-1,""))) -> #REF!
A14: ='1 - Staff Calendar View'!$A$7 -> Wk 11 | B14: ='1 - Staff Calendar View'!D$6 -> 46210 | C14: =TEXT(B14,"ddd") -> Tue | D14: ='1 - Staff Calendar View'!$B$13 -> Webinar Faciliator | E14: =VLOOKUP(D14,'1 - Staff Calendar View'!$I$49:$J$51,2,FALSE()) -> #N/A | F14: ='1 - Staff Calendar View'!D$13 | G14: =IF('1 - Staff Calendar View'!D$14="-","-",'1 - Staff Calendar View'!D$14) | H14: =IF('2 - My Shifts'!$C$4="","",IF(OR(F14="-",F14=""),"",IF(UPPER(TRIM(F14))=UPPER(TRIM('2 - My Shifts'!$C$4)),ROW()-1,""))) -> #REF!
A15: ='1 - Staff Calendar View'!$A$7 -> Wk 11 | B15: ='1 - Staff Calendar View'!D$6 -> 46210 | C15: =TEXT(B15,"ddd") -> Tue | D15: ='1 - Staff Calendar View'!$B$13 -> Webinar Faciliator | E15: =VLOOKUP(D15,'1 - Staff Calendar View'!$I$49:$J$51,2,FALSE()) -> #N/A | F15: ='1 - Staff Calendar View'!D$14 | G15: =IF('1 - Staff Calendar View'!D$13="-","-",'1 - Staff Calendar View'!D$13) | H15: =IF('2 - My Shifts'!$C$4="","",IF(OR(F15="-",F15=""),"",IF(UPPER(TRIM(F15))=UPPER(TRIM('2 - My Shifts'!$C$4)),ROW()-1,""))) -> #REF!
A16: ='1 - Staff Calendar View'!$A$7 -> Wk 11 | B16: ='1 - Staff Calendar View'!D$6 -> 46210 | C16: =TEXT(B16,"ddd") -> Tue | D16: ='1 - Staff Calendar View'!$B$16 | E16: =VLOOKUP(D16,'1 - Staff Calendar View'!$I$49:$J$51,2,FALSE()) -> #N/A | F16: ='1 - Staff Calendar View'!D$16 | G16: =IF('1 - Staff Calendar View'!D$18="-","-",'1 - Staff Calendar View'!D$18) | H16: =IF('2 - My Shifts'!$C$4="","",IF(OR(F16="-",F16=""),"",IF(UPPER(TRIM(F16))=UPPER(TRIM('2 - My Shifts'!$C$4)),ROW()-1,""))) -> #REF!
A17: ='1 - Staff Calendar View'!$A$7 -> Wk 11 | B17: ='1 - Staff Calendar View'!D$6 -> 46210 | C17: =TEXT(B17,"ddd") -> Tue | D17: ='1 - Staff Calendar View'!$B$16 | E17: =VLOOKUP(D17,'1 - Staff Calendar View'!$I$49:$J$51,2,FALSE()) -> #N/A | F17: ='1 - Staff Calendar View'!D$18 | G17: =IF('1 - Staff Calendar View'!D$16="-","-",'1 - Staff Calendar View'!D$16) | H17: =IF('2 - My Shifts'!$C$4="","",IF(OR(F17="-",F17=""),"",IF(UPPER(TRIM(F17))=UPPER(TRIM('2 - My Shifts'!$C$4)),ROW()-1,""))) -> #REF!
A18: ='1 - Staff Calendar View'!$A$7 -> Wk 11 | B18: ='1 - Staff Calendar View'!E$6 -> 46211 | C18: =TEXT(B18,"ddd") -> Wed | D18: ='1 - Staff Calendar View'!$B$7 -> Clayton Drop-in | E18: =VLOOKUP(D18,'1 - Staff Calendar View'!$I$49:$J$51,2,FALSE()) -> #N/A | F18: ='1 - Staff Calendar View'!E$7 -> Sener | G18: =IF('1 - Staff Calendar View'!E$9="-","-",'1 - Staff Calendar View'!E$9) -> Advay | H18: =IF('2 - My Shifts'!$C$4="","",IF(OR(F18="-",F18=""),"",IF(UPPER(TRIM(F18))=UPPER(TRIM('2 - My Shifts'!$C$4)),ROW()-1,""))) -> #REF!
A19: ='1 - Staff Calendar View'!$A$7 -> Wk 11 | B19: ='1 - Staff Calendar View'!E$6 -> 46211 | C19: =TEXT(B19,"ddd") -> Wed | D19: ='1 - Staff Calendar View'!$B$7 -> Clayton Drop-in | E19: =VLOOKUP(D19,'1 - Staff Calendar View'!$I$49:$J$51,2,FALSE()) -> #N/A | F19: ='1 - Staff Calendar View'!E$9 -> Advay | G19: =IF('1 - Staff Calendar View'!E$7="-","-",'1 - Staff Calendar View'!E$7) -> Sener | H19: =IF('2 - My Shifts'!$C$4="","",IF(OR(F19="-",F19=""),"",IF(UPPER(TRIM(F19))=UPPER(TRIM('2 - My Shifts'!$C$4)),ROW()-1,""))) -> #REF!
A20: ='1 - Staff Calendar View'!$A$7 -> Wk 11 | B20: ='1 - Staff Calendar View'!E$6 -> 46211 | C20: =TEXT(B20,"ddd") -> Wed | D20: ='1 - Staff Calendar View'!$B$10 -> Caulfield Drop-in | E20: =VLOOKUP(D20,'1 - Staff Calendar View'!$I$49:$J$51,2,FALSE()) -> 10:40AM-2:20PM | F20: ='1 - Staff Calendar View'!E$10 -> Jamein | G20: =IF('1 - Staff Calendar View'!E$12="-","-",'1 - Staff Calendar View'!E$12) | H20: =IF('2 - My Shifts'!$C$4="","",IF(OR(F20="-",F20=""),"",IF(UPPER(TRIM(F20))=UPPER(TRIM('2 - My Shifts'!$C$4)),ROW()-1,""))) -> #REF!
A21: ='1 - Staff Calendar View'!$A$7 -> Wk 11 | B21: ='1 - Staff Calendar View'!E$6 -> 46211 | C21: =TEXT(B21,"ddd") -> Wed | D21: ='1 - Staff Calendar View'!$B$10 -> Caulfield Drop-in | E21: =VLOOKUP(D21,'1 - Staff Calendar View'!$I$49:$J$51,2,FALSE()) -> 10:40AM-2:20PM | F21: ='1 - Staff Calendar View'!E$12 | G21: =IF('1 - Staff Calendar View'!E$10="-","-",'1 - Staff Calendar View'!E$10) -> Jamein | H21: =IF('2 - My Shifts'!$C$4="","",IF(OR(F21="-",F21=""),"",IF(UPPER(TRIM(F21))=UPPER(TRIM('2 - My Shifts'!$C$4)),ROW()-1,""))) -> #REF!
A22: ='1 - Staff Calendar View'!$A$7 -> Wk 11 | B22: ='1 - Staff Calendar View'!E$6 -> 46211 | C22: =TEXT(B22,"ddd") -> Wed | D22: ='1 - Staff Calendar View'!$B$13 -> Webinar Faciliator | E22: =VLOOKUP(D22,'1 - Staff Calendar View'!$I$49:$J$51,2,FALSE()) -> #N/A | F22: ='1 - Staff Calendar View'!E$13 -> Omila | G22: =IF('1 - Staff Calendar View'!E$14="-","-",'1 - Staff Calendar View'!E$14) -> Grace | H22: =IF('2 - My Shifts'!$C$4="","",IF(OR(F22="-",F22=""),"",IF(UPPER(TRIM(F22))=UPPER(TRIM('2 - My Shifts'!$C$4)),ROW()-1,""))) -> #REF!
A23: ='1 - Staff Calendar View'!$A$7 -> Wk 11 | B23: ='1 - Staff Calendar View'!E$6 -> 46211 | C23: =TEXT(B23,"ddd") -> Wed | D23: ='1 - Staff Calendar View'!$B$13 -> Webinar Faciliator | E23: =VLOOKUP(D23,'1 - Staff Calendar View'!$I$49:$J$51,2,FALSE()) -> #N/A | F23: ='1 - Staff Calendar View'!E$14 -> Grace | G23: =IF('1 - Staff Calendar View'!E$13="-","-",'1 - Staff Calendar View'!E$13) -> Omila | H23: =IF('2 - My Shifts'!$C$4="","",IF(OR(F23="-",F23=""),"",IF(UPPER(TRIM(F23))=UPPER(TRIM('2 - My Shifts'!$C$4)),ROW()-1,""))) -> #REF!
A24: ='1 - Staff Calendar View'!$A$7 -> Wk 11 | B24: ='1 - Staff Calendar View'!E$6 -> 46211 | C24: =TEXT(B24,"ddd") -> Wed | D24: ='1 - Staff Calendar View'!$B$16 | E24: =VLOOKUP(D24,'1 - Staff Calendar View'!$I$49:$J$51,2,FALSE()) -> #N/A | F24: ='1 - Staff Calendar View'!E$16 -> Ekachit | G24: =IF('1 - Staff Calendar View'!E$18="-","-",'1 - Staff Calendar View'!E$18) | H24: =IF('2 - My Shifts'!$C$4="","",IF(OR(F24="-",F24=""),"",IF(UPPER(TRIM(F24))=UPPER(TRIM('2 - My Shifts'!$C$4)),ROW()-1,""))) -> #REF!
A25: ='1 - Staff Calendar View'!$A$7 -> Wk 11 | B25: ='1 - Staff Calendar View'!E$6 -> 46211 | C25: =TEXT(B25,"ddd") -> Wed | D25: ='1 - Staff Calendar View'!$B$16 | E25: =VLOOKUP(D25,'1 - Staff Calendar View'!$I$49:$J$51,2,FALSE()) -> #N/A | F25: ='1 - Staff Calendar View'!E$18 | G25: =IF('1 - Staff Calendar View'!E$16="-","-",'1 - Staff Calendar View'!E$16) -> Ekachit | H25: =IF('2 - My Shifts'!$C$4="","",IF(OR(F25="-",F25=""),"",IF(UPPER(TRIM(F25))=UPPER(TRIM('2 - My Shifts'!$C$4)),ROW()-1,""))) -> #REF!
A26: ='1 - Staff Calendar View'!$A$7 -> Wk 11 | B26: ='1 - Staff Calendar View'!F$6 -> 46212 | C26: =TEXT(B26,"ddd") -> Thu | D26: ='1 - Staff Calendar View'!$B$7 -> Clayton Drop-in | E26: =VLOOKUP(D26,'1 - Staff Calendar View'!$I$49:$J$51,2,FALSE()) -> #N/A | F26: ='1 - Staff Calendar View'!F$7 -> Omila | G26: =IF('1 - Staff Calendar View'!F$9="-","-",'1 - Staff Calendar View'!F$9) | H26: =IF('2 - My Shifts'!$C$4="","",IF(OR(F26="-",F26=""),"",IF(UPPER(TRIM(F26))=UPPER(TRIM('2 - My Shifts'!$C$4)),ROW()-1,""))) -> #REF!
A27: ='1 - Staff Calendar View'!$A$7 -> Wk 11 | B27: ='1 - Staff Calendar View'!F$6 -> 46212 | C27: =TEXT(B27,"ddd") -> Thu | D27: ='1 - Staff Calendar View'!$B$7 -> Clayton Drop-in | E27: =VLOOKUP(D27,'1 - Staff Calendar View'!$I$49:$J$51,2,FALSE()) -> #N/A | F27: ='1 - Staff Calendar View'!F$9 | G27: =IF('1 - Staff Calendar View'!F$7="-","-",'1 - Staff Calendar View'!F$7) -> Omila | H27: =IF('2 - My Shifts'!$C$4="","",IF(OR(F27="-",F27=""),"",IF(UPPER(TRIM(F27))=UPPER(TRIM('2 - My Shifts'!$C$4)),ROW()-1,""))) -> #REF!
A28: ='1 - Staff Calendar View'!$A$7 -> Wk 11 | B28: ='1 - Staff Calendar View'!F$6 -> 46212 | C28: =TEXT(B28,"ddd") -> Thu | D28: ='1 - Staff Calendar View'!$B$10 -> Caulfield Drop-in | E28: =VLOOKUP(D28,'1 - Staff Calendar View'!$I$49:$J$51,2,FALSE()) -> 10:40AM-2:20PM | F28: ='1 - Staff Calendar View'!F$10 -> Sener | G28: =IF('1 - Staff Calendar View'!F$12="-","-",'1 - Staff Calendar View'!F$12) | H28: =IF('2 - My Shifts'!$C$4="","",IF(OR(F28="-",F28=""),"",IF(UPPER(TRIM(F28))=UPPER(TRIM('2 - My Shifts'!$C$4)),ROW()-1,""))) -> #REF!
A29: ='1 - Staff Calendar View'!$A$7 -> Wk 11 | B29: ='1 - Staff Calendar View'!F$6 -> 46212 | C29: =TEXT(B29,"ddd") -> Thu | D29: ='1 - Staff Calendar View'!$B$10 -> Caulfield Drop-in | E29: =VLOOKUP(D29,'1 - Staff Calendar View'!$I$49:$J$51,2,FALSE()) -> 10:40AM-2:20PM | F29: ='1 - Staff Calendar View'!F$12 | G29: =IF('1 - Staff Calendar View'!F$10="-","-",'1 - Staff Calendar View'!F$10) -> Sener | H29: =IF('2 - My Shifts'!$C$4="","",IF(OR(F29="-",F29=""),"",IF(UPPER(TRIM(F29))=UPPER(TRIM('2 - My Shifts'!$C$4)),ROW()-1,""))) -> #REF!
A30: ='1 - Staff Calendar View'!$A$7 -> Wk 11 | B30: ='1 - Staff Calendar View'!F$6 -> 46212 | C30: =TEXT(B30,"ddd") -> Thu | D30: ='1 - Staff Calendar View'!$B$13 -> Webinar Faciliator | E30: =VLOOKUP(D30,'1 - Staff Calendar View'!$I$49:$J$51,2,FALSE()) -> #N/A | F30: ='1 - Staff Calendar View'!F$13 | G30: =IF('1 - Staff Calendar View'!F$14="-","-",'1 - Staff Calendar View'!F$14) | H30: =IF('2 - My Shifts'!$C$4="","",IF(OR(F30="-",F30=""),"",IF(UPPER(TRIM(F30))=UPPER(TRIM('2 - My Shifts'!$C$4)),ROW()-1,""))) -> #REF!
A31: ='1 - Staff Calendar View'!$A$7 -> Wk 11 | B31: ='1 - Staff Calendar View'!F$6 -> 46212 | C31: =TEXT(B31,"ddd") -> Thu | D31: ='1 - Staff Calendar View'!$B$13 -> Webinar Faciliator | E31: =VLOOKUP(D31,'1 - Staff Calendar View'!$I$49:$J$51,2,FALSE()) -> #N/A | F31: ='1 - Staff Calendar View'!F$14 | G31: =IF('1 - Staff Calendar View'!F$13="-","-",'1 - Staff Calendar View'!F$13) | H31: =IF('2 - My Shifts'!$C$4="","",IF(OR(F31="-",F31=""),"",IF(UPPER(TRIM(F31))=UPPER(TRIM('2 - My Shifts'!$C$4)),ROW()-1,""))) -> #REF!
A32: ='1 - Staff Calendar View'!$A$7 -> Wk 11 | B32: ='1 - Staff Calendar View'!F$6 -> 46212 | C32: =TEXT(B32,"ddd") -> Thu | D32: ='1 - Staff Calendar View'!$B$16 | E32: =VLOOKUP(D32,'1 - Staff Calendar View'!$I$49:$J$51,2,FALSE()) -> #N/A | F32: ='1 - Staff Calendar View'!F$16 | G32: =IF('1 - Staff Calendar View'!F$18="-","-",'1 - Staff Calendar View'!F$18) | H32: =IF('2 - My Shifts'!$C$4="","",IF(OR(F32="-",F32=""),"",IF(UPPER(TRIM(F32))=UPPER(TRIM('2 - My Shifts'!$C$4)),ROW()-1,""))) -> #REF!
A33: ='1 - Staff Calendar View'!$A$7 -> Wk 11 | B33: ='1 - Staff Calendar View'!F$6 -> 46212 | C33: =TEXT(B33,"ddd") -> Thu | D33: ='1 - Staff Calendar View'!$B$16 | E33: =VLOOKUP(D33,'1 - Staff Calendar View'!$I$49:$J$51,2,FALSE()) -> #N/A | F33: ='1 - Staff Calendar View'!F$18 | G33: =IF('1 - Staff Calendar View'!F$16="-","-",'1 - Staff Calendar View'!F$16) | H33: =IF('2 - My Shifts'!$C$4="","",IF(OR(F33="-",F33=""),"",IF(UPPER(TRIM(F33))=UPPER(TRIM('2 - My Shifts'!$C$4)),ROW()-1,""))) -> #REF!
A34: ='1 - Staff Calendar View'!$A$7 -> Wk 11 | B34: ='1 - Staff Calendar View'!G$6 -> 46213 | C34: =TEXT(B34,"ddd") -> Fri | D34: ='1 - Staff Calendar View'!$B$7 -> Clayton Drop-in | E34: =VLOOKUP(D34,'1 - Staff Calendar View'!$I$49:$J$51,2,FALSE()) -> #N/A | F34: ='1 - Staff Calendar View'!G$7 | G34: =IF('1 - Staff Calendar View'!G$9="-","-",'1 - Staff Calendar View'!G$9) | H34: =IF('2 - My Shifts'!$C$4="","",IF(OR(F34="-",F34=""),"",IF(UPPER(TRIM(F34))=UPPER(TRIM('2 - My Shifts'!$C$4)),ROW()-1,""))) -> #REF!
A35: ='1 - Staff Calendar View'!$A$7 -> Wk 11 | B35: ='1 - Staff Calendar View'!G$6 -> 46213 | C35: =TEXT(B35,"ddd") -> Fri | D35: ='1 - Staff Calendar View'!$B$7 -> Clayton Drop-in | E35: =VLOOKUP(D35,'1 - Staff Calendar View'!$I$49:$J$51,2,FALSE()) -> #N/A | F35: ='1 - Staff Calendar View'!G$9 | G35: =IF('1 - Staff Calendar View'!G$7="-","-",'1 - Staff Calendar View'!G$7) | H35: =IF('2 - My Shifts'!$C$4="","",IF(OR(F35="-",F35=""),"",IF(UPPER(TRIM(F35))=UPPER(TRIM('2 - My Shifts'!$C$4)),ROW()-1,""))) -> #REF!
A36: ='1 - Staff Calendar View'!$A$7 -> Wk 11 | B36: ='1 - Staff Calendar View'!G$6 -> 46213 | C36: =TEXT(B36,"ddd") -> Fri | D36: ='1 - Staff Calendar View'!$B$10 -> Caulfield Drop-in | E36: =VLOOKUP(D36,'1 - Staff Calendar View'!$I$49:$J$51,2,FALSE()) -> 10:40AM-2:20PM | F36: ='1 - Staff Calendar View'!G$10 | G36: =IF('1 - Staff Calendar View'!G$12="-","-",'1 - Staff Calendar View'!G$12) | H36: =IF('2 - My Shifts'!$C$4="","",IF(OR(F36="-",F36=""),"",IF(UPPER(TRIM(F36))=UPPER(TRIM('2 - My Shifts'!$C$4)),ROW()-1,""))) -> #REF!
A37: ='1 - Staff Calendar View'!$A$7 -> Wk 11 | B37: ='1 - Staff Calendar View'!G$6 -> 46213 | C37: =TEXT(B37,"ddd") -> Fri | D37: ='1 - Staff Calendar View'!$B$10 -> Caulfield Drop-in | E37: =VLOOKUP(D37,'1 - Staff Calendar View'!$I$49:$J$51,2,FALSE()) -> 10:40AM-2:20PM | F37: ='1 - Staff Calendar View'!G$12 | G37: =IF('1 - Staff Calendar View'!G$10="-","-",'1 - Staff Calendar View'!G$10) | H37: =IF('2 - My Shifts'!$C$4="","",IF(OR(F37="-",F37=""),"",IF(UPPER(TRIM(F37))=UPPER(TRIM('2 - My Shifts'!$C$4)),ROW()-1,""))) -> #REF!
A38: ='1 - Staff Calendar View'!$A$7 -> Wk 11 | B38: ='1 - Staff Calendar View'!G$6 -> 46213 | C38: =TEXT(B38,"ddd") -> Fri | D38: ='1 - Staff Calendar View'!$B$13 -> Webinar Faciliator | E38: =VLOOKUP(D38,'1 - Staff Calendar View'!$I$49:$J$51,2,FALSE()) -> #N/A | F38: ='1 - Staff Calendar View'!G$13 | G38: =IF('1 - Staff Calendar View'!G$14="-","-",'1 - Staff Calendar View'!G$14) | H38: =IF('2 - My Shifts'!$C$4="","",IF(OR(F38="-",F38=""),"",IF(UPPER(TRIM(F38))=UPPER(TRIM('2 - My Shifts'!$C$4)),ROW()-1,""))) -> #REF!
A39: ='1 - Staff Calendar View'!$A$7 -> Wk 11 | B39: ='1 - Staff Calendar View'!G$6 -> 46213 | C39: =TEXT(B39,"ddd") -> Fri | D39: ='1 - Staff Calendar View'!$B$13 -> Webinar Faciliator | E39: =VLOOKUP(D39,'1 - Staff Calendar View'!$I$49:$J$51,2,FALSE()) -> #N/A | F39: ='1 - Staff Calendar View'!G$14 | G39: =IF('1 - Staff Calendar View'!G$13="-","-",'1 - Staff Calendar View'!G$13) | H39: =IF('2 - My Shifts'!$C$4="","",IF(OR(F39="-",F39=""),"",IF(UPPER(TRIM(F39))=UPPER(TRIM('2 - My Shifts'!$C$4)),ROW()-1,""))) -> #REF!
A40: ='1 - Staff Calendar View'!$A$7 -> Wk 11 | B40: ='1 - Staff Calendar View'!G$6 -> 46213 | C40: =TEXT(B40,"ddd") -> Fri | D40: ='1 - Staff Calendar View'!$B$16 | E40: =VLOOKUP(D40,'1 - Staff Calendar View'!$I$49:$J$51,2,FALSE()) -> #N/A | F40: ='1 - Staff Calendar View'!G$16 | G40: =IF('1 - Staff Calendar View'!G$18="-","-",'1 - Staff Calendar View'!G$18) -> All Staff | H40: =IF('2 - My Shifts'!$C$4="","",IF(OR(F40="-",F40=""),"",IF(UPPER(TRIM(F40))=UPPER(TRIM('2 - My Shifts'!$C$4)),ROW()-1,""))) -> #REF!
...
